[2024-04-14T09:31:35.447+0000] {local_task_job_runner.py:120} INFO - ::group::Pre task execution logs
[2024-04-14T09:31:35.487+0000] {taskinstance.py:2073} INFO - Dependencies all met for dep_context=non-requeueable deps ti=<TaskInstance: etl.load_filtered_data_to_bigquery manual__2024-04-14T05:09:56.705108+00:00 [queued]>
[2024-04-14T09:31:35.507+0000] {taskinstance.py:2073} INFO - Dependencies all met for dep_context=requeueable deps ti=<TaskInstance: etl.load_filtered_data_to_bigquery manual__2024-04-14T05:09:56.705108+00:00 [queued]>
[2024-04-14T09:31:35.507+0000] {taskinstance.py:2303} INFO - Starting attempt 4 of 4
[2024-04-14T09:31:35.538+0000] {taskinstance.py:2327} INFO - Executing <Task(BigQueryExecuteQueryOperator): load_filtered_data_to_bigquery> on 2024-04-14 05:09:56.705108+00:00
[2024-04-14T09:31:35.552+0000] {logging_mixin.py:188} WARNING - /home/***/.local/lib/python3.12/site-packages/***/task/task_runner/standard_task_runner.py:61 DeprecationWarning: This process (pid=157996) is multi-threaded, use of fork() may lead to deadlocks in the child.
[2024-04-14T09:31:35.553+0000] {standard_task_runner.py:63} INFO - Started process 158018 to run task
[2024-04-14T09:31:35.558+0000] {standard_task_runner.py:90} INFO - Running: ['***', 'tasks', 'run', 'etl', 'load_filtered_data_to_bigquery', 'manual__2024-04-14T05:09:56.705108+00:00', '--job-id', '89', '--raw', '--subdir', 'DAGS_FOLDER/etl.py', '--cfg-path', '/tmp/tmpsum8qtux']
[2024-04-14T09:31:35.559+0000] {standard_task_runner.py:91} INFO - Job 89: Subtask load_filtered_data_to_bigquery
[2024-04-14T09:31:35.616+0000] {task_command.py:426} INFO - Running <TaskInstance: etl.load_filtered_data_to_bigquery manual__2024-04-14T05:09:56.705108+00:00 [running]> on host 2ce858e27684
[2024-04-14T09:31:35.687+0000] {taskinstance.py:2644} INFO - Exporting env vars: AIRFLOW_CTX_DAG_OWNER='***' AIRFLOW_CTX_DAG_ID='etl' AIRFLOW_CTX_TASK_ID='load_filtered_data_to_bigquery' AIRFLOW_CTX_EXECUTION_DATE='2024-04-14T05:09:56.705108+00:00' AIRFLOW_CTX_TRY_NUMBER='4' AIRFLOW_CTX_DAG_RUN_ID='manual__2024-04-14T05:09:56.705108+00:00'
[2024-04-14T09:31:35.689+0000] {taskinstance.py:430} INFO - ::endgroup::
[2024-04-14T09:31:35.690+0000] {bigquery.py:1246} INFO - Executing: SELECT No,paymenttype FROM order_bazilian.csv
[2024-04-14T09:31:35.696+0000] {connection.py:274} WARNING - Connection schemes (type: google_cloud_platform) shall not contain '_' according to RFC3986.
[2024-04-14T09:31:35.700+0000] {base.py:84} INFO - Using connection ID 'my_gcp_conn' for task execution.
[2024-04-14T09:31:35.702+0000] {logging_mixin.py:188} WARNING - /home/***/.local/lib/python3.12/site-packages/***/providers/google/cloud/operators/bigquery.py:1254 AirflowProviderDeprecationWarning: Call to deprecated method run_query. (Please use `***.providers.google.cloud.hooks.bigquery.BigQueryHook.insert_job`)
[2024-04-14T09:31:35.749+0000] {bigquery.py:1613} INFO - Inserting job ***_1713087095749102_baa51ec0b1fdd49f2614bdec1309817c
[2024-04-14T09:31:36.409+0000] {taskinstance.py:441} INFO - ::group::Post task execution logs
[2024-04-14T09:31:36.409+0000] {taskinstance.py:2890} ERROR - Task failed with exception
Traceback (most recent call last):
  File "/home/airflow/.local/lib/python3.12/site-packages/airflow/models/taskinstance.py", line 465, in _execute_task
    result = _execute_callable(context=context, **execute_callable_kwargs)
             ^^^^^^^^^^^^^^^^^^^^^^^^^^^^^^^^^^^^^^^^^^^^^^^^^^^^^^^^^^^^^
  File "/home/airflow/.local/lib/python3.12/site-packages/airflow/models/taskinstance.py", line 432, in _execute_callable
    return execute_callable(context=context, **execute_callable_kwargs)
           ^^^^^^^^^^^^^^^^^^^^^^^^^^^^^^^^^^^^^^^^^^^^^^^^^^^^^^^^^^^^
  File "/home/airflow/.local/lib/python3.12/site-packages/airflow/models/baseoperator.py", line 400, in wrapper
    return func(self, *args, **kwargs)
           ^^^^^^^^^^^^^^^^^^^^^^^^^^^
  File "/home/airflow/.local/lib/python3.12/site-packages/airflow/providers/google/cloud/operators/bigquery.py", line 1254, in execute
    self.job_id = self.hook.run_query(
                  ^^^^^^^^^^^^^^^^^^^^
  File "/home/airflow/.local/lib/python3.12/site-packages/deprecated/classic.py", line 285, in wrapper_function
    return wrapped_(*args_, **kwargs_)
           ^^^^^^^^^^^^^^^^^^^^^^^^^^^
  File "/home/airflow/.local/lib/python3.12/site-packages/airflow/providers/google/cloud/hooks/bigquery.py", line 2258, in run_query
    job = self.insert_job(configuration=configuration, project_id=self.project_id, location=location)
          ^^^^^^^^^^^^^^^^^^^^^^^^^^^^^^^^^^^^^^^^^^^^^^^^^^^^^^^^^^^^^^^^^^^^^^^^^^^^^^^^^^^^^^^^^^^
  File "/home/airflow/.local/lib/python3.12/site-packages/airflow/providers/google/common/hooks/base_google.py", line 485, in inner_wrapper
    return func(self, *args, **kwargs)
           ^^^^^^^^^^^^^^^^^^^^^^^^^^^
  File "/home/airflow/.local/lib/python3.12/site-packages/airflow/providers/google/cloud/hooks/bigquery.py", line 1619, in insert_job
    job_api_repr.result(timeout=timeout, retry=retry)
  File "/home/airflow/.local/lib/python3.12/site-packages/google/cloud/bigquery/job/query.py", line 1590, in result
    do_get_result()
  File "/home/airflow/.local/lib/python3.12/site-packages/google/cloud/bigquery/job/query.py", line 1579, in do_get_result
    super(QueryJob, self).result(retry=retry, timeout=timeout)
  File "/home/airflow/.local/lib/python3.12/site-packages/google/cloud/bigquery/job/base.py", line 971, in result
    return super(_AsyncJob, self).result(timeout=timeout, **kwargs)
           ^^^^^^^^^^^^^^^^^^^^^^^^^^^^^^^^^^^^^^^^^^^^^^^^^^^^^^^^
  File "/home/airflow/.local/lib/python3.12/site-packages/google/api_core/future/polling.py", line 261, in result
    raise self._exception
google.api_core.exceptions.NotFound: 404 Not found: Dataset dataengineer-415510:order_bazilian was not found in location US; reason: notFound, message: Not found: Dataset dataengineer-415510:order_bazilian was not found in location US

Location: US
Job ID: airflow_1713087095749102_baa51ec0b1fdd49f2614bdec1309817c

[2024-04-14T09:31:36.424+0000] {taskinstance.py:1205} INFO - Marking task as FAILED. dag_id=etl, task_id=load_filtered_data_to_bigquery, execution_date=20240414T050956, start_date=20240414T093135, end_date=20240414T093136
[2024-04-14T09:31:36.445+0000] {standard_task_runner.py:110} ERROR - Failed to execute job 89 for task load_filtered_data_to_bigquery (404 Not found: Dataset dataengineer-415510:order_bazilian was not found in location US; reason: notFound, message: Not found: Dataset dataengineer-415510:order_bazilian was not found in location US

Location: US
Job ID: airflow_1713087095749102_baa51ec0b1fdd49f2614bdec1309817c
; 158018)
[2024-04-14T09:31:36.463+0000] {local_task_job_runner.py:240} INFO - Task exited with return code 1
[2024-04-14T09:31:36.481+0000] {taskinstance.py:3482} INFO - 0 downstream tasks scheduled from follow-on schedule check
[2024-04-14T09:31:36.491+0000] {local_task_job_runner.py:222} INFO - ::endgroup::
