[2024-04-25T16:12:29.342+0000] {local_task_job_runner.py:120} INFO - ::group::Pre task execution logs
[2024-04-25T16:12:29.354+0000] {taskinstance.py:2073} INFO - Dependencies all met for dep_context=non-requeueable deps ti=<TaskInstance: dbt.dbt_run manual__2024-04-25T12:31:24.548079+00:00 [queued]>
[2024-04-25T16:12:29.360+0000] {taskinstance.py:2073} INFO - Dependencies all met for dep_context=requeueable deps ti=<TaskInstance: dbt.dbt_run manual__2024-04-25T12:31:24.548079+00:00 [queued]>
[2024-04-25T16:12:29.360+0000] {taskinstance.py:2303} INFO - Starting attempt 9 of 9
[2024-04-25T16:12:29.375+0000] {taskinstance.py:2327} INFO - Executing <Task(BashOperator): dbt_run> on 2024-04-25 12:31:24.548079+00:00
[2024-04-25T16:12:29.385+0000] {standard_task_runner.py:90} INFO - Running: ['***', 'tasks', 'run', 'dbt', 'dbt_run', 'manual__2024-04-25T12:31:24.548079+00:00', '--job-id', '338', '--raw', '--subdir', 'DAGS_FOLDER/bq_dbt.py', '--cfg-path', '/tmp/tmp_hu7zcki']
[2024-04-25T16:12:29.387+0000] {standard_task_runner.py:91} INFO - Job 338: Subtask dbt_run
[2024-04-25T16:12:29.389+0000] {logging_mixin.py:188} WARNING - /home/***/.local/lib/python3.12/site-packages/***/task/task_runner/standard_task_runner.py:61 DeprecationWarning: This process (pid=120897) is multi-threaded, use of fork() may lead to deadlocks in the child.
[2024-04-25T16:12:29.390+0000] {standard_task_runner.py:63} INFO - Started process 120899 to run task
[2024-04-25T16:12:29.428+0000] {task_command.py:426} INFO - Running <TaskInstance: dbt.dbt_run manual__2024-04-25T12:31:24.548079+00:00 [running]> on host b619dce40a27
[2024-04-25T16:12:29.675+0000] {taskinstance.py:2644} INFO - Exporting env vars: AIRFLOW_CTX_DAG_OWNER='***' AIRFLOW_CTX_DAG_ID='dbt' AIRFLOW_CTX_TASK_ID='dbt_run' AIRFLOW_CTX_EXECUTION_DATE='2024-04-25T12:31:24.548079+00:00' AIRFLOW_CTX_TRY_NUMBER='9' AIRFLOW_CTX_DAG_RUN_ID='manual__2024-04-25T12:31:24.548079+00:00'
[2024-04-25T16:12:29.676+0000] {taskinstance.py:430} INFO - ::endgroup::
[2024-04-25T16:12:29.676+0000] {subprocess.py:63} INFO - Tmp dir root location: /tmp
[2024-04-25T16:12:29.677+0000] {subprocess.py:75} INFO - Running command: ['/usr/bin/bash', '-c', 'cd /workspaces/dw-and-bi/Capstone-project; source ENV/bin/activate; cd projectcapstone/; dbt run']
[2024-04-25T16:12:29.691+0000] {subprocess.py:86} INFO - Output:
[2024-04-25T16:12:29.693+0000] {subprocess.py:93} INFO - /usr/bin/bash: line 1: cd: /workspaces/dw-and-bi/Capstone-project: No such file or directory
[2024-04-25T16:12:29.693+0000] {subprocess.py:93} INFO - /usr/bin/bash: line 1: ENV/bin/activate: No such file or directory
[2024-04-25T16:12:29.694+0000] {subprocess.py:93} INFO - /usr/bin/bash: line 1: cd: projectcapstone/: No such file or directory
[2024-04-25T16:12:29.694+0000] {subprocess.py:93} INFO - /usr/bin/bash: line 1: dbt: command not found
[2024-04-25T16:12:29.694+0000] {subprocess.py:97} INFO - Command exited with return code 127
[2024-04-25T16:12:29.695+0000] {taskinstance.py:441} INFO - ::group::Post task execution logs
[2024-04-25T16:12:29.703+0000] {taskinstance.py:2890} ERROR - Task failed with exception
Traceback (most recent call last):
  File "/home/airflow/.local/lib/python3.12/site-packages/airflow/models/taskinstance.py", line 465, in _execute_task
    result = _execute_callable(context=context, **execute_callable_kwargs)
             ^^^^^^^^^^^^^^^^^^^^^^^^^^^^^^^^^^^^^^^^^^^^^^^^^^^^^^^^^^^^^
  File "/home/airflow/.local/lib/python3.12/site-packages/airflow/models/taskinstance.py", line 432, in _execute_callable
    return execute_callable(context=context, **execute_callable_kwargs)
           ^^^^^^^^^^^^^^^^^^^^^^^^^^^^^^^^^^^^^^^^^^^^^^^^^^^^^^^^^^^^
  File "/home/airflow/.local/lib/python3.12/site-packages/airflow/models/baseoperator.py", line 400, in wrapper
    return func(self, *args, **kwargs)
           ^^^^^^^^^^^^^^^^^^^^^^^^^^^
  File "/home/airflow/.local/lib/python3.12/site-packages/airflow/operators/bash.py", line 243, in execute
    raise AirflowException(
airflow.exceptions.AirflowException: Bash command failed. The command returned a non-zero exit code 127.
[2024-04-25T16:12:29.705+0000] {taskinstance.py:1205} INFO - Marking task as FAILED. dag_id=dbt, task_id=dbt_run, execution_date=20240425T123124, start_date=20240425T161229, end_date=20240425T161229
[2024-04-25T16:12:29.719+0000] {standard_task_runner.py:110} ERROR - Failed to execute job 338 for task dbt_run (Bash command failed. The command returned a non-zero exit code 127.; 120899)
[2024-04-25T16:12:29.764+0000] {local_task_job_runner.py:240} INFO - Task exited with return code 1
[2024-04-25T16:12:29.780+0000] {taskinstance.py:3482} INFO - 0 downstream tasks scheduled from follow-on schedule check
[2024-04-25T16:12:29.789+0000] {local_task_job_runner.py:222} INFO - ::endgroup::
