[2024-04-26T16:30:41.377+0000] {local_task_job_runner.py:120} INFO - ::group::Pre task execution logs
[2024-04-26T16:30:41.416+0000] {taskinstance.py:2073} INFO - Dependencies all met for dep_context=non-requeueable deps ti=<TaskInstance: dbt.run_dbt_model manual__2024-04-26T16:27:05.020494+00:00 [queued]>
[2024-04-26T16:30:41.428+0000] {taskinstance.py:2073} INFO - Dependencies all met for dep_context=requeueable deps ti=<TaskInstance: dbt.run_dbt_model manual__2024-04-26T16:27:05.020494+00:00 [queued]>
[2024-04-26T16:30:41.430+0000] {taskinstance.py:2303} INFO - Starting attempt 2 of 2
[2024-04-26T16:30:41.462+0000] {taskinstance.py:2327} INFO - Executing <Task(BashOperator): run_dbt_model> on 2024-04-26 16:27:05.020494+00:00
[2024-04-26T16:30:41.484+0000] {logging_mixin.py:188} WARNING - /home/***/.local/lib/python3.12/site-packages/***/task/task_runner/standard_task_runner.py:61 DeprecationWarning: This process (pid=122782) is multi-threaded, use of fork() may lead to deadlocks in the child.
[2024-04-26T16:30:41.490+0000] {standard_task_runner.py:63} INFO - Started process 122820 to run task
[2024-04-26T16:30:41.501+0000] {standard_task_runner.py:90} INFO - Running: ['***', 'tasks', 'run', 'dbt', 'run_dbt_model', 'manual__2024-04-26T16:27:05.020494+00:00', '--job-id', '378', '--raw', '--subdir', 'DAGS_FOLDER/bq_dbt.py', '--cfg-path', '/tmp/tmpadc64d1a']
[2024-04-26T16:30:41.510+0000] {standard_task_runner.py:91} INFO - Job 378: Subtask run_dbt_model
[2024-04-26T16:30:41.588+0000] {task_command.py:426} INFO - Running <TaskInstance: dbt.run_dbt_model manual__2024-04-26T16:27:05.020494+00:00 [running]> on host b619dce40a27
[2024-04-26T16:30:41.718+0000] {taskinstance.py:2644} INFO - Exporting env vars: AIRFLOW_CTX_DAG_OWNER='***' AIRFLOW_CTX_DAG_ID='dbt' AIRFLOW_CTX_TASK_ID='run_dbt_model' AIRFLOW_CTX_EXECUTION_DATE='2024-04-26T16:27:05.020494+00:00' AIRFLOW_CTX_TRY_NUMBER='2' AIRFLOW_CTX_DAG_RUN_ID='manual__2024-04-26T16:27:05.020494+00:00'
[2024-04-26T16:30:41.720+0000] {taskinstance.py:430} INFO - ::endgroup::
[2024-04-26T16:30:41.721+0000] {subprocess.py:63} INFO - Tmp dir root location: /tmp
[2024-04-26T16:30:41.722+0000] {subprocess.py:75} INFO - Running command: ['/usr/bin/bash', '-c', 'dbt run --project-dir /workspaces/dw-and-bi/Capstone-project --profiles-dir /workspaces/dw-and-bi/Capstone-project/projectcapstone/profiles.yml']
[2024-04-26T16:30:41.776+0000] {subprocess.py:86} INFO - Output:
[2024-04-26T16:30:41.783+0000] {subprocess.py:93} INFO - /usr/bin/bash: line 1: dbt: command not found
[2024-04-26T16:30:41.787+0000] {subprocess.py:97} INFO - Command exited with return code 127
[2024-04-26T16:30:41.788+0000] {taskinstance.py:441} INFO - ::group::Post task execution logs
[2024-04-26T16:30:41.800+0000] {taskinstance.py:2890} ERROR - Task failed with exception
Traceback (most recent call last):
  File "/home/airflow/.local/lib/python3.12/site-packages/airflow/models/taskinstance.py", line 465, in _execute_task
    result = _execute_callable(context=context, **execute_callable_kwargs)
             ^^^^^^^^^^^^^^^^^^^^^^^^^^^^^^^^^^^^^^^^^^^^^^^^^^^^^^^^^^^^^
  File "/home/airflow/.local/lib/python3.12/site-packages/airflow/models/taskinstance.py", line 432, in _execute_callable
    return execute_callable(context=context, **execute_callable_kwargs)
           ^^^^^^^^^^^^^^^^^^^^^^^^^^^^^^^^^^^^^^^^^^^^^^^^^^^^^^^^^^^^
  File "/home/airflow/.local/lib/python3.12/site-packages/airflow/models/baseoperator.py", line 400, in wrapper
    return func(self, *args, **kwargs)
           ^^^^^^^^^^^^^^^^^^^^^^^^^^^
  File "/home/airflow/.local/lib/python3.12/site-packages/airflow/operators/bash.py", line 243, in execute
    raise AirflowException(
airflow.exceptions.AirflowException: Bash command failed. The command returned a non-zero exit code 127.
[2024-04-26T16:30:41.812+0000] {taskinstance.py:1205} INFO - Marking task as FAILED. dag_id=dbt, task_id=run_dbt_model, execution_date=20240426T162705, start_date=20240426T163041, end_date=20240426T163041
[2024-04-26T16:30:41.842+0000] {standard_task_runner.py:110} ERROR - Failed to execute job 378 for task run_dbt_model (Bash command failed. The command returned a non-zero exit code 127.; 122820)
[2024-04-26T16:30:41.870+0000] {local_task_job_runner.py:240} INFO - Task exited with return code 1
[2024-04-26T16:30:41.907+0000] {taskinstance.py:3482} INFO - 0 downstream tasks scheduled from follow-on schedule check
[2024-04-26T16:30:41.919+0000] {local_task_job_runner.py:222} INFO - ::endgroup::
