[2024-04-14T13:33:31.125+0000] {local_task_job_runner.py:120} INFO - ::group::Pre task execution logs
[2024-04-14T13:33:31.137+0000] {taskinstance.py:2073} INFO - Dependencies all met for dep_context=non-requeueable deps ti=<TaskInstance: etl.load_data_into_new_table manual__2024-04-14T10:15:09.605913+00:00 [queued]>
[2024-04-14T13:33:31.145+0000] {taskinstance.py:2073} INFO - Dependencies all met for dep_context=requeueable deps ti=<TaskInstance: etl.load_data_into_new_table manual__2024-04-14T10:15:09.605913+00:00 [queued]>
[2024-04-14T13:33:31.145+0000] {taskinstance.py:2303} INFO - Starting attempt 6 of 6
[2024-04-14T13:33:31.164+0000] {taskinstance.py:2327} INFO - Executing <Task(BigQueryInsertJobOperator): load_data_into_new_table> on 2024-04-14 10:15:09.605913+00:00
[2024-04-14T13:33:31.174+0000] {standard_task_runner.py:90} INFO - Running: ['***', 'tasks', 'run', 'etl', 'load_data_into_new_table', 'manual__2024-04-14T10:15:09.605913+00:00', '--job-id', '123', '--raw', '--subdir', 'DAGS_FOLDER/etl.py', '--cfg-path', '/tmp/tmpy2ay_61v']
[2024-04-14T13:33:31.176+0000] {standard_task_runner.py:91} INFO - Job 123: Subtask load_data_into_new_table
[2024-04-14T13:33:31.177+0000] {logging_mixin.py:188} WARNING - /home/***/.local/lib/python3.12/site-packages/***/task/task_runner/standard_task_runner.py:61 DeprecationWarning: This process (pid=2584) is multi-threaded, use of fork() may lead to deadlocks in the child.
[2024-04-14T13:33:31.178+0000] {standard_task_runner.py:63} INFO - Started process 2601 to run task
[2024-04-14T13:33:31.241+0000] {task_command.py:426} INFO - Running <TaskInstance: etl.load_data_into_new_table manual__2024-04-14T10:15:09.605913+00:00 [running]> on host 2ce858e27684
[2024-04-14T13:33:31.377+0000] {taskinstance.py:2644} INFO - Exporting env vars: AIRFLOW_CTX_DAG_OWNER='***' AIRFLOW_CTX_DAG_ID='etl' AIRFLOW_CTX_TASK_ID='load_data_into_new_table' AIRFLOW_CTX_EXECUTION_DATE='2024-04-14T10:15:09.605913+00:00' AIRFLOW_CTX_TRY_NUMBER='6' AIRFLOW_CTX_DAG_RUN_ID='manual__2024-04-14T10:15:09.605913+00:00'
[2024-04-14T13:33:31.378+0000] {taskinstance.py:430} INFO - ::endgroup::
[2024-04-14T13:33:31.386+0000] {connection.py:274} WARNING - Connection schemes (type: google_cloud_platform) shall not contain '_' according to RFC3986.
[2024-04-14T13:33:31.390+0000] {base.py:84} INFO - Using connection ID 'my_gcp_conn' for task execution.
[2024-04-14T13:33:31.436+0000] {bigquery.py:2811} INFO - Executing: {'query': {'query': "\n            CREATE OR REPLACE TABLE `dataengineer-415510.order.Finance`\n            AS Finance\n            SELECT \n            'No', \n            'paymenttype'\n            FROM `dataengineer-415510.order.dataset_order` \n            ", 'useLegacySql': False}}'
[2024-04-14T13:33:31.437+0000] {bigquery.py:1613} INFO - Inserting job ***_etl_load_data_into_new_table_2024_04_14T10_15_09_605913_00_00_c841804208e4f7b9c2571c249ab052e7
[2024-04-14T13:33:31.956+0000] {taskinstance.py:441} INFO - ::group::Post task execution logs
[2024-04-14T13:33:31.957+0000] {taskinstance.py:2890} ERROR - Task failed with exception
Traceback (most recent call last):
  File "/home/airflow/.local/lib/python3.12/site-packages/airflow/models/taskinstance.py", line 465, in _execute_task
    result = _execute_callable(context=context, **execute_callable_kwargs)
             ^^^^^^^^^^^^^^^^^^^^^^^^^^^^^^^^^^^^^^^^^^^^^^^^^^^^^^^^^^^^^
  File "/home/airflow/.local/lib/python3.12/site-packages/airflow/models/taskinstance.py", line 432, in _execute_callable
    return execute_callable(context=context, **execute_callable_kwargs)
           ^^^^^^^^^^^^^^^^^^^^^^^^^^^^^^^^^^^^^^^^^^^^^^^^^^^^^^^^^^^^
  File "/home/airflow/.local/lib/python3.12/site-packages/airflow/models/baseoperator.py", line 400, in wrapper
    return func(self, *args, **kwargs)
           ^^^^^^^^^^^^^^^^^^^^^^^^^^^
  File "/home/airflow/.local/lib/python3.12/site-packages/airflow/providers/google/cloud/operators/bigquery.py", line 2870, in execute
    job.result(timeout=self.result_timeout, retry=self.result_retry)
  File "/home/airflow/.local/lib/python3.12/site-packages/google/cloud/bigquery/job/query.py", line 1590, in result
    do_get_result()
  File "/home/airflow/.local/lib/python3.12/site-packages/google/cloud/bigquery/job/query.py", line 1579, in do_get_result
    super(QueryJob, self).result(retry=retry, timeout=timeout)
  File "/home/airflow/.local/lib/python3.12/site-packages/google/cloud/bigquery/job/base.py", line 971, in result
    return super(_AsyncJob, self).result(timeout=timeout, **kwargs)
           ^^^^^^^^^^^^^^^^^^^^^^^^^^^^^^^^^^^^^^^^^^^^^^^^^^^^^^^^
  File "/home/airflow/.local/lib/python3.12/site-packages/google/api_core/future/polling.py", line 261, in result
    raise self._exception
google.api_core.exceptions.BadRequest: 400 Syntax error: Unexpected identifier "Finance" at [3:16]; reason: invalidQuery, location: query, message: Syntax error: Unexpected identifier "Finance" at [3:16]

Location: US
Job ID: airflow_etl_load_data_into_new_table_2024_04_14T10_15_09_605913_00_00_c841804208e4f7b9c2571c249ab052e7

[2024-04-14T13:33:31.985+0000] {taskinstance.py:1205} INFO - Marking task as FAILED. dag_id=etl, task_id=load_data_into_new_table, execution_date=20240414T101509, start_date=20240414T133331, end_date=20240414T133331
[2024-04-14T13:33:32.041+0000] {standard_task_runner.py:110} ERROR - Failed to execute job 123 for task load_data_into_new_table (400 Syntax error: Unexpected identifier "Finance" at [3:16]; reason: invalidQuery, location: query, message: Syntax error: Unexpected identifier "Finance" at [3:16]

Location: US
Job ID: airflow_etl_load_data_into_new_table_2024_04_14T10_15_09_605913_00_00_c841804208e4f7b9c2571c249ab052e7
; 2601)
[2024-04-14T13:33:32.089+0000] {local_task_job_runner.py:240} INFO - Task exited with return code 1
[2024-04-14T13:33:32.109+0000] {taskinstance.py:3482} INFO - 0 downstream tasks scheduled from follow-on schedule check
[2024-04-14T13:33:32.130+0000] {local_task_job_runner.py:222} INFO - ::endgroup::
