[2024-04-14T11:07:15.677+0000] {local_task_job_runner.py:120} INFO - ::group::Pre task execution logs
[2024-04-14T11:07:15.695+0000] {taskinstance.py:2073} INFO - Dependencies all met for dep_context=non-requeueable deps ti=<TaskInstance: etl.load_data_into_new_table manual__2024-04-14T10:15:09.605913+00:00 [queued]>
[2024-04-14T11:07:15.704+0000] {taskinstance.py:2073} INFO - Dependencies all met for dep_context=requeueable deps ti=<TaskInstance: etl.load_data_into_new_table manual__2024-04-14T10:15:09.605913+00:00 [queued]>
[2024-04-14T11:07:15.705+0000] {taskinstance.py:2303} INFO - Starting attempt 1 of 1
[2024-04-14T11:07:15.726+0000] {taskinstance.py:2327} INFO - Executing <Task(BigQueryInsertJobOperator): load_data_into_new_table> on 2024-04-14 10:15:09.605913+00:00
[2024-04-14T11:07:15.740+0000] {logging_mixin.py:188} WARNING - /home/***/.local/lib/python3.12/site-packages/***/task/task_runner/standard_task_runner.py:61 DeprecationWarning: This process (pid=208251) is multi-threaded, use of fork() may lead to deadlocks in the child.
[2024-04-14T11:07:15.741+0000] {standard_task_runner.py:63} INFO - Started process 208263 to run task
[2024-04-14T11:07:15.746+0000] {standard_task_runner.py:90} INFO - Running: ['***', 'tasks', 'run', 'etl', 'load_data_into_new_table', 'manual__2024-04-14T10:15:09.605913+00:00', '--job-id', '112', '--raw', '--subdir', 'DAGS_FOLDER/etl.py', '--cfg-path', '/tmp/tmpj_4ztvr5']
[2024-04-14T11:07:15.747+0000] {standard_task_runner.py:91} INFO - Job 112: Subtask load_data_into_new_table
[2024-04-14T11:07:15.806+0000] {task_command.py:426} INFO - Running <TaskInstance: etl.load_data_into_new_table manual__2024-04-14T10:15:09.605913+00:00 [running]> on host 2ce858e27684
[2024-04-14T11:07:15.976+0000] {taskinstance.py:2644} INFO - Exporting env vars: AIRFLOW_CTX_DAG_OWNER='***' AIRFLOW_CTX_DAG_ID='etl' AIRFLOW_CTX_TASK_ID='load_data_into_new_table' AIRFLOW_CTX_EXECUTION_DATE='2024-04-14T10:15:09.605913+00:00' AIRFLOW_CTX_TRY_NUMBER='1' AIRFLOW_CTX_DAG_RUN_ID='manual__2024-04-14T10:15:09.605913+00:00'
[2024-04-14T11:07:15.980+0000] {taskinstance.py:430} INFO - ::endgroup::
[2024-04-14T11:07:15.994+0000] {taskinstance.py:441} INFO - ::group::Post task execution logs
[2024-04-14T11:07:16.005+0000] {taskinstance.py:2890} ERROR - Task failed with exception
Traceback (most recent call last):
  File "/home/airflow/.local/lib/python3.12/site-packages/airflow/models/taskinstance.py", line 465, in _execute_task
    result = _execute_callable(context=context, **execute_callable_kwargs)
             ^^^^^^^^^^^^^^^^^^^^^^^^^^^^^^^^^^^^^^^^^^^^^^^^^^^^^^^^^^^^^
  File "/home/airflow/.local/lib/python3.12/site-packages/airflow/models/taskinstance.py", line 432, in _execute_callable
    return execute_callable(context=context, **execute_callable_kwargs)
           ^^^^^^^^^^^^^^^^^^^^^^^^^^^^^^^^^^^^^^^^^^^^^^^^^^^^^^^^^^^^
  File "/home/airflow/.local/lib/python3.12/site-packages/airflow/models/baseoperator.py", line 400, in wrapper
    return func(self, *args, **kwargs)
           ^^^^^^^^^^^^^^^^^^^^^^^^^^^
  File "/home/airflow/.local/lib/python3.12/site-packages/airflow/providers/google/cloud/operators/bigquery.py", line 2793, in execute
    hook = BigQueryHook(
           ^^^^^^^^^^^^^
  File "/home/airflow/.local/lib/python3.12/site-packages/airflow/providers/google/cloud/hooks/bigquery.py", line 119, in __init__
    super().__init__(
  File "/home/airflow/.local/lib/python3.12/site-packages/airflow/providers/google/common/hooks/base_google.py", line 251, in __init__
    self.extras: dict = self.get_connection(self.gcp_conn_id).extra_dejson
                        ^^^^^^^^^^^^^^^^^^^^^^^^^^^^^^^^^^^^^
  File "/home/airflow/.local/lib/python3.12/site-packages/airflow/hooks/base.py", line 83, in get_connection
    conn = Connection.get_connection_from_secrets(conn_id)
           ^^^^^^^^^^^^^^^^^^^^^^^^^^^^^^^^^^^^^^^^^^^^^^^
  File "/home/airflow/.local/lib/python3.12/site-packages/airflow/models/connection.py", line 519, in get_connection_from_secrets
    raise AirflowNotFoundException(f"The conn_id `{conn_id}` isn't defined")
airflow.exceptions.AirflowNotFoundException: The conn_id `google_cloud_default` isn't defined
[2024-04-14T11:07:16.011+0000] {taskinstance.py:1205} INFO - Marking task as FAILED. dag_id=etl, task_id=load_data_into_new_table, execution_date=20240414T101509, start_date=20240414T110715, end_date=20240414T110716
[2024-04-14T11:07:16.035+0000] {standard_task_runner.py:110} ERROR - Failed to execute job 112 for task load_data_into_new_table (The conn_id `google_cloud_default` isn't defined; 208263)
[2024-04-14T11:07:16.066+0000] {local_task_job_runner.py:240} INFO - Task exited with return code 1
[2024-04-14T11:07:16.113+0000] {taskinstance.py:3482} INFO - 0 downstream tasks scheduled from follow-on schedule check
[2024-04-14T11:07:16.121+0000] {local_task_job_runner.py:222} INFO - ::endgroup::
