[2024-04-13T17:35:31.002+0000] {local_task_job_runner.py:120} INFO - ::group::Pre task execution logs
[2024-04-13T17:35:31.014+0000] {taskinstance.py:2073} INFO - Dependencies all met for dep_context=non-requeueable deps ti=<TaskInstance: etl.upload_file_to_bucket manual__2024-04-13T17:17:33.443854+00:00 [queued]>
[2024-04-13T17:35:31.019+0000] {taskinstance.py:2073} INFO - Dependencies all met for dep_context=requeueable deps ti=<TaskInstance: etl.upload_file_to_bucket manual__2024-04-13T17:17:33.443854+00:00 [queued]>
[2024-04-13T17:35:31.020+0000] {taskinstance.py:2303} INFO - Starting attempt 9 of 9
[2024-04-13T17:35:31.034+0000] {taskinstance.py:2327} INFO - Executing <Task(LocalFilesystemToGCSOperator): upload_file_to_bucket> on 2024-04-13 17:17:33.443854+00:00
[2024-04-13T17:35:31.044+0000] {standard_task_runner.py:90} INFO - Running: ['***', 'tasks', 'run', 'etl', 'upload_file_to_bucket', 'manual__2024-04-13T17:17:33.443854+00:00', '--job-id', '22', '--raw', '--subdir', 'DAGS_FOLDER/etl.py', '--cfg-path', '/tmp/tmpk2eurwjh']
[2024-04-13T17:35:31.046+0000] {standard_task_runner.py:91} INFO - Job 22: Subtask upload_file_to_bucket
[2024-04-13T17:35:31.048+0000] {logging_mixin.py:188} WARNING - /home/***/.local/lib/python3.12/site-packages/***/task/task_runner/standard_task_runner.py:61 DeprecationWarning: This process (pid=51696) is multi-threaded, use of fork() may lead to deadlocks in the child.
[2024-04-13T17:35:31.048+0000] {standard_task_runner.py:63} INFO - Started process 51708 to run task
[2024-04-13T17:35:31.089+0000] {task_command.py:426} INFO - Running <TaskInstance: etl.upload_file_to_bucket manual__2024-04-13T17:17:33.443854+00:00 [running]> on host 2ce858e27684
[2024-04-13T17:35:31.159+0000] {taskinstance.py:2644} INFO - Exporting env vars: AIRFLOW_CTX_DAG_OWNER='***' AIRFLOW_CTX_DAG_ID='etl' AIRFLOW_CTX_TASK_ID='upload_file_to_bucket' AIRFLOW_CTX_EXECUTION_DATE='2024-04-13T17:17:33.443854+00:00' AIRFLOW_CTX_TRY_NUMBER='9' AIRFLOW_CTX_DAG_RUN_ID='manual__2024-04-13T17:17:33.443854+00:00'
[2024-04-13T17:35:31.161+0000] {taskinstance.py:430} INFO - ::endgroup::
[2024-04-13T17:35:31.167+0000] {connection.py:274} WARNING - Connection schemes (type: google_cloud_platform) shall not contain '_' according to RFC3986.
[2024-04-13T17:35:31.172+0000] {base.py:84} INFO - Using connection ID 'my_gcp_conn' for task execution.
[2024-04-13T17:35:31.870+0000] {gcs.py:512} ERROR - Upload attempt of object: gs://swu-ds525-load-data-to-bigquery/order_bazilian.csv from gs://swu-ds525-load-data-to-bigquery/order_bazilian.csv has failed. Attempt: 1, max 1.
[2024-04-13T17:35:31.870+0000] {taskinstance.py:441} INFO - ::group::Post task execution logs
[2024-04-13T17:35:31.870+0000] {taskinstance.py:2890} ERROR - Task failed with exception
Traceback (most recent call last):
  File "/home/airflow/.local/lib/python3.12/site-packages/google/cloud/storage/blob.py", line 2637, in _prep_and_do_upload
    created_json = self._do_upload(
                   ^^^^^^^^^^^^^^^^
  File "/home/airflow/.local/lib/python3.12/site-packages/google/cloud/storage/blob.py", line 2460, in _do_upload
    response = self._do_resumable_upload(
               ^^^^^^^^^^^^^^^^^^^^^^^^^^
  File "/home/airflow/.local/lib/python3.12/site-packages/google/cloud/storage/blob.py", line 2278, in _do_resumable_upload
    upload, transport = self._initiate_resumable_upload(
                        ^^^^^^^^^^^^^^^^^^^^^^^^^^^^^^^^
  File "/home/airflow/.local/lib/python3.12/site-packages/google/cloud/storage/blob.py", line 2152, in _initiate_resumable_upload
    upload.initiate(
  File "/home/airflow/.local/lib/python3.12/site-packages/google/resumable_media/requests/upload.py", line 420, in initiate
    return _request_helpers.wait_and_retry(
           ^^^^^^^^^^^^^^^^^^^^^^^^^^^^^^^^
  File "/home/airflow/.local/lib/python3.12/site-packages/google/resumable_media/requests/_request_helpers.py", line 155, in wait_and_retry
    response = func()
               ^^^^^^
  File "/home/airflow/.local/lib/python3.12/site-packages/google/resumable_media/requests/upload.py", line 416, in retriable_request
    self._process_initiate_response(result)
  File "/home/airflow/.local/lib/python3.12/site-packages/google/resumable_media/_upload.py", line 518, in _process_initiate_response
    _helpers.require_status_code(
  File "/home/airflow/.local/lib/python3.12/site-packages/google/resumable_media/_helpers.py", line 108, in require_status_code
    raise common.InvalidResponse(
google.resumable_media.common.InvalidResponse: ('Request failed with status code', 404, 'Expected one of', 200, 201)

During handling of the above exception, another exception occurred:

Traceback (most recent call last):
  File "/home/airflow/.local/lib/python3.12/site-packages/airflow/models/taskinstance.py", line 465, in _execute_task
    result = _execute_callable(context=context, **execute_callable_kwargs)
             ^^^^^^^^^^^^^^^^^^^^^^^^^^^^^^^^^^^^^^^^^^^^^^^^^^^^^^^^^^^^^
  File "/home/airflow/.local/lib/python3.12/site-packages/airflow/models/taskinstance.py", line 432, in _execute_callable
    return execute_callable(context=context, **execute_callable_kwargs)
           ^^^^^^^^^^^^^^^^^^^^^^^^^^^^^^^^^^^^^^^^^^^^^^^^^^^^^^^^^^^^
  File "/home/airflow/.local/lib/python3.12/site-packages/airflow/models/baseoperator.py", line 400, in wrapper
    return func(self, *args, **kwargs)
           ^^^^^^^^^^^^^^^^^^^^^^^^^^^
  File "/home/airflow/.local/lib/python3.12/site-packages/airflow/providers/google/cloud/transfers/local_to_gcs.py", line 110, in execute
    hook.upload(
  File "/home/airflow/.local/lib/python3.12/site-packages/airflow/providers/google/cloud/hooks/gcs.py", line 551, in upload
    _call_with_retry(
  File "/home/airflow/.local/lib/python3.12/site-packages/airflow/providers/google/cloud/hooks/gcs.py", line 519, in _call_with_retry
    raise e
  File "/home/airflow/.local/lib/python3.12/site-packages/airflow/providers/google/cloud/hooks/gcs.py", line 509, in _call_with_retry
    f()
  File "/home/airflow/.local/lib/python3.12/site-packages/google/cloud/storage/blob.py", line 2959, in upload_from_filename
    self._handle_filename_and_upload(
  File "/home/airflow/.local/lib/python3.12/site-packages/google/cloud/storage/blob.py", line 2829, in _handle_filename_and_upload
    self._prep_and_do_upload(
  File "/home/airflow/.local/lib/python3.12/site-packages/google/cloud/storage/blob.py", line 2655, in _prep_and_do_upload
    _raise_from_invalid_response(exc)
  File "/home/airflow/.local/lib/python3.12/site-packages/google/cloud/storage/blob.py", line 4847, in _raise_from_invalid_response
    raise exceptions.from_http_status(response.status_code, message, response=response)
google.api_core.exceptions.NotFound: 404 POST https://storage.googleapis.com/upload/storage/v1/b/swu-ds525-load-data-to-bigquery/o?uploadType=resumable: {
  "error": {
    "code": 404,
    "message": "The specified bucket does not exist.",
    "errors": [
      {
        "message": "The specified bucket does not exist.",
        "domain": "global",
        "reason": "notFound"
      }
    ]
  }
}
: ('Request failed with status code', 404, 'Expected one of', <HTTPStatus.OK: 200>, <HTTPStatus.CREATED: 201>)
[2024-04-13T17:35:31.880+0000] {taskinstance.py:1205} INFO - Marking task as FAILED. dag_id=etl, task_id=upload_file_to_bucket, execution_date=20240413T171733, start_date=20240413T173531, end_date=20240413T173531
[2024-04-13T17:35:31.892+0000] {standard_task_runner.py:110} ERROR - Failed to execute job 22 for task upload_file_to_bucket (404 POST https://storage.googleapis.com/upload/storage/v1/b/swu-ds525-load-data-to-bigquery/o?uploadType=resumable: {
  "error": {
    "code": 404,
    "message": "The specified bucket does not exist.",
    "errors": [
      {
        "message": "The specified bucket does not exist.",
        "domain": "global",
        "reason": "notFound"
      }
    ]
  }
}
: ('Request failed with status code', 404, 'Expected one of', <HTTPStatus.OK: 200>, <HTTPStatus.CREATED: 201>); 51708)
[2024-04-13T17:35:31.903+0000] {local_task_job_runner.py:240} INFO - Task exited with return code 1
[2024-04-13T17:35:31.917+0000] {taskinstance.py:3482} INFO - 0 downstream tasks scheduled from follow-on schedule check
[2024-04-13T17:35:31.923+0000] {local_task_job_runner.py:222} INFO - ::endgroup::
