[2024-04-22T06:34:42.492+0000] {task_context_logger.py:104} ERROR - Executor reports task instance <TaskInstance: etl.upload_file_geolocation scheduled__2024-04-20T00:00:00+00:00 [queued]> finished (failed) although the task says it's queued. (Info: None) Was the task killed externally?
