[2024-04-14T10:15:22.072+0000] {local_task_job_runner.py:120} INFO - ::group::Pre task execution logs
[2024-04-14T10:15:22.089+0000] {taskinstance.py:2073} INFO - Dependencies all met for dep_context=non-requeueable deps ti=<TaskInstance: etl.create_table manual__2024-04-14T10:15:09.605913+00:00 [queued]>
[2024-04-14T10:15:22.095+0000] {taskinstance.py:2073} INFO - Dependencies all met for dep_context=requeueable deps ti=<TaskInstance: etl.create_table manual__2024-04-14T10:15:09.605913+00:00 [queued]>
[2024-04-14T10:15:22.095+0000] {taskinstance.py:2303} INFO - Starting attempt 1 of 1
[2024-04-14T10:15:22.109+0000] {taskinstance.py:2327} INFO - Executing <Task(BigQueryExecuteQueryOperator): create_table> on 2024-04-14 10:15:09.605913+00:00
[2024-04-14T10:15:22.121+0000] {logging_mixin.py:188} WARNING - /home/***/.local/lib/python3.12/site-packages/***/task/task_runner/standard_task_runner.py:61 DeprecationWarning: This process (pid=180966) is multi-threaded, use of fork() may lead to deadlocks in the child.
[2024-04-14T10:15:22.121+0000] {standard_task_runner.py:90} INFO - Running: ['***', 'tasks', 'run', 'etl', 'create_table', 'manual__2024-04-14T10:15:09.605913+00:00', '--job-id', '96', '--raw', '--subdir', 'DAGS_FOLDER/etl.py', '--cfg-path', '/tmp/tmpkf39cnz0']
[2024-04-14T10:15:22.122+0000] {standard_task_runner.py:63} INFO - Started process 180978 to run task
[2024-04-14T10:15:22.122+0000] {standard_task_runner.py:91} INFO - Job 96: Subtask create_table
[2024-04-14T10:15:22.161+0000] {task_command.py:426} INFO - Running <TaskInstance: etl.create_table manual__2024-04-14T10:15:09.605913+00:00 [running]> on host 2ce858e27684
[2024-04-14T10:15:22.235+0000] {taskinstance.py:2644} INFO - Exporting env vars: AIRFLOW_CTX_DAG_OWNER='***' AIRFLOW_CTX_DAG_ID='etl' AIRFLOW_CTX_TASK_ID='create_table' AIRFLOW_CTX_EXECUTION_DATE='2024-04-14T10:15:09.605913+00:00' AIRFLOW_CTX_TRY_NUMBER='1' AIRFLOW_CTX_DAG_RUN_ID='manual__2024-04-14T10:15:09.605913+00:00'
[2024-04-14T10:15:22.237+0000] {taskinstance.py:430} INFO - ::endgroup::
[2024-04-14T10:15:22.237+0000] {bigquery.py:1246} INFO - Executing: CREATE TABLE 'dataengineer-415510.order.Finance' (No STRING, paymenttype STRING)
[2024-04-14T10:15:22.244+0000] {connection.py:274} WARNING - Connection schemes (type: google_cloud_platform) shall not contain '_' according to RFC3986.
[2024-04-14T10:15:22.248+0000] {base.py:84} INFO - Using connection ID 'my_gcp_conn' for task execution.
[2024-04-14T10:15:22.250+0000] {logging_mixin.py:188} WARNING - /home/***/.local/lib/python3.12/site-packages/***/providers/google/cloud/operators/bigquery.py:1254 AirflowProviderDeprecationWarning: Call to deprecated method run_query. (Please use `***.providers.google.cloud.hooks.bigquery.BigQueryHook.insert_job`)
[2024-04-14T10:15:22.297+0000] {bigquery.py:1613} INFO - Inserting job ***_1713089722296586_652012d59094295eb6b9339730232244
[2024-04-14T10:15:22.757+0000] {taskinstance.py:441} INFO - ::group::Post task execution logs
[2024-04-14T10:15:22.758+0000] {taskinstance.py:2890} ERROR - Task failed with exception
Traceback (most recent call last):
  File "/home/airflow/.local/lib/python3.12/site-packages/airflow/models/taskinstance.py", line 465, in _execute_task
    result = _execute_callable(context=context, **execute_callable_kwargs)
             ^^^^^^^^^^^^^^^^^^^^^^^^^^^^^^^^^^^^^^^^^^^^^^^^^^^^^^^^^^^^^
  File "/home/airflow/.local/lib/python3.12/site-packages/airflow/models/taskinstance.py", line 432, in _execute_callable
    return execute_callable(context=context, **execute_callable_kwargs)
           ^^^^^^^^^^^^^^^^^^^^^^^^^^^^^^^^^^^^^^^^^^^^^^^^^^^^^^^^^^^^
  File "/home/airflow/.local/lib/python3.12/site-packages/airflow/models/baseoperator.py", line 400, in wrapper
    return func(self, *args, **kwargs)
           ^^^^^^^^^^^^^^^^^^^^^^^^^^^
  File "/home/airflow/.local/lib/python3.12/site-packages/airflow/providers/google/cloud/operators/bigquery.py", line 1254, in execute
    self.job_id = self.hook.run_query(
                  ^^^^^^^^^^^^^^^^^^^^
  File "/home/airflow/.local/lib/python3.12/site-packages/deprecated/classic.py", line 285, in wrapper_function
    return wrapped_(*args_, **kwargs_)
           ^^^^^^^^^^^^^^^^^^^^^^^^^^^
  File "/home/airflow/.local/lib/python3.12/site-packages/airflow/providers/google/cloud/hooks/bigquery.py", line 2258, in run_query
    job = self.insert_job(configuration=configuration, project_id=self.project_id, location=location)
          ^^^^^^^^^^^^^^^^^^^^^^^^^^^^^^^^^^^^^^^^^^^^^^^^^^^^^^^^^^^^^^^^^^^^^^^^^^^^^^^^^^^^^^^^^^^
  File "/home/airflow/.local/lib/python3.12/site-packages/airflow/providers/google/common/hooks/base_google.py", line 485, in inner_wrapper
    return func(self, *args, **kwargs)
           ^^^^^^^^^^^^^^^^^^^^^^^^^^^
  File "/home/airflow/.local/lib/python3.12/site-packages/airflow/providers/google/cloud/hooks/bigquery.py", line 1619, in insert_job
    job_api_repr.result(timeout=timeout, retry=retry)
  File "/home/airflow/.local/lib/python3.12/site-packages/google/cloud/bigquery/job/query.py", line 1590, in result
    do_get_result()
  File "/home/airflow/.local/lib/python3.12/site-packages/google/cloud/bigquery/job/query.py", line 1579, in do_get_result
    super(QueryJob, self).result(retry=retry, timeout=timeout)
  File "/home/airflow/.local/lib/python3.12/site-packages/google/cloud/bigquery/job/base.py", line 971, in result
    return super(_AsyncJob, self).result(timeout=timeout, **kwargs)
           ^^^^^^^^^^^^^^^^^^^^^^^^^^^^^^^^^^^^^^^^^^^^^^^^^^^^^^^^
  File "/home/airflow/.local/lib/python3.12/site-packages/google/api_core/future/polling.py", line 261, in result
    raise self._exception
google.api_core.exceptions.BadRequest: 400 Encountered "" at line 1, column 14.
; reason: invalidQuery, location: query, message: Encountered "" at line 1, column 14.


Location: US
Job ID: airflow_1713089722296586_652012d59094295eb6b9339730232244

[2024-04-14T10:15:22.767+0000] {taskinstance.py:1205} INFO - Marking task as FAILED. dag_id=etl, task_id=create_table, execution_date=20240414T101509, start_date=20240414T101522, end_date=20240414T101522
[2024-04-14T10:15:22.781+0000] {standard_task_runner.py:110} ERROR - Failed to execute job 96 for task create_table (400 Encountered "" at line 1, column 14.
; reason: invalidQuery, location: query, message: Encountered "" at line 1, column 14.


Location: US
Job ID: airflow_1713089722296586_652012d59094295eb6b9339730232244
; 180978)
[2024-04-14T10:15:22.818+0000] {local_task_job_runner.py:240} INFO - Task exited with return code 1
[2024-04-14T10:15:22.827+0000] {logging_mixin.py:188} WARNING - /home/***/.local/lib/python3.12/site-packages/***/models/baseoperator.py:1296 AirflowProviderDeprecationWarning: Call to deprecated class BigQueryExecuteQueryOperator. (This operator is deprecated. Please use `BigQueryInsertJobOperator`.)
[2024-04-14T10:15:22.836+0000] {taskinstance.py:3482} INFO - 0 downstream tasks scheduled from follow-on schedule check
[2024-04-14T10:15:22.844+0000] {local_task_job_runner.py:222} INFO - ::endgroup::
