[2024-04-14T06:49:00.716+0000] {task_context_logger.py:104} ERROR - Executor reports task instance <TaskInstance: etl.load_dataset_Finance manual__2024-04-14T05:09:56.705108+00:00 [queued]> finished (failed) although the task says it's queued. (Info: None) Was the task killed externally?
[2024-04-14T06:49:11.958+0000] {task_context_logger.py:104} ERROR - Executor reports task instance <TaskInstance: etl.load_dataset_Finance manual__2024-04-14T05:09:56.705108+00:00 [queued]> finished (failed) although the task says it's queued. (Info: None) Was the task killed externally?
[2024-04-14T06:49:40.790+0000] {task_context_logger.py:104} ERROR - Executor reports task instance <TaskInstance: etl.load_dataset_Finance manual__2024-04-14T05:09:56.705108+00:00 [queued]> finished (failed) although the task says it's queued. (Info: None) Was the task killed externally?
